#VRML_SIM R2021a utf8
WorldInfo {
  coordinateSystem "NUE"
}
Viewpoint {
  orientation 1 0 0 4.71238898038469
  position 0.0012745942137962314 3.412426525803567 2.5518378734743844e-09
  follow "table"
}
TexturedBackground {
}
TexturedBackgroundLight {
}
DEF OBJECTS Group {
  children [
    Floor {
      name "floor(1)"
    }
    DEF TABLE Table {
      size 1.22 0.76 0.76
      frameThickness 0.1
    }
  ]
}
DEF TableUV Robot {
  translation -1.1919446714331297e-07 0.7869679433500472 -1.7674686513222782e-11
  rotation -0.0001482848968909727 4.058376648053027e-11 0.9999999890057946 4.417475680697026e-06
  children [
    DEF ROBOT_IMU_ACC Accelerometer {
      name "imu_acc"
    }
    DEF ROBOT_IMU_GYRO Gyro {
      name "imu_gyro"
    }
    DEF ROBOT_IMU_COMP Compass {
      name "imu_comp"
    }
    DEF ROBOT_TOF RangeFinder {
      translation 0 0 0.02
      rotation 0 1 0 3.14159
      name "tof"
      fieldOfView 0.471
      maxRange 4
    }
    Solid {
      translation 0 -0.017 0.02
      children [
        DEF CASTER_WHEEL Shape {
          appearance PBRAppearance {
            metalness 0
          }
          geometry Sphere {
            radius 0.01
          }
        }
      ]
      name "caster_wheel"
      boundingObject USE CASTER_WHEEL
      physics Physics {
      }
    }
    Solid {
      translation 0 -0.017 -0.02
      children [
        DEF CASTER_WHEEL Shape {
          appearance PBRAppearance {
            metalness 0
          }
          geometry Sphere {
            radius 0.01
          }
        }
      ]
      name "caster_wheel(1)"
      boundingObject USE CASTER_WHEEL
      physics Physics {
      }
    }
    HingeJoint {
      jointParameters HingeJointParameters {
        position 7.414499819166283e-08
        anchor -0.04 -0.01 0
      }
      device [
        DEF ROBOT_ENC_RIGHT PositionSensor {
          name "right_ps"
        }
        RotationalMotor {
          name "right_motor"
        }
      ]
      endPoint Solid {
        translation -0.04000000040198491 -0.009998878983036004 5.8474013930815415e-09
        rotation 1.5461376827233608e-08 -1.518241006380056e-08 0.9999999999999998 1.569999953030221
        children [
          DEF WHEEL Shape {
            appearance PBRAppearance {
              metalness 0
            }
            geometry DEF ROBOT_WHEEL_RIGHT Cylinder {
              height 0.006
              radius 0.017
            }
          }
        ]
        name "solid(1)"
        boundingObject USE WHEEL
        physics DEF WHEEL_PHYS Physics {
        }
      }
    }
    HingeJoint {
      jointParameters HingeJointParameters {
        position 3.187094133621833e-08
        anchor 0.04 -0.01 0
      }
      device [
        DEF ROBOT_ENC_LEFT PositionSensor {
          name "left_ps"
        }
        RotationalMotor {
          name "left_motor"
        }
      ]
      endPoint Solid {
        translation 0.04 -0.00999889 4.164319999985571e-09
        rotation 9.142179752134203e-10 -1.182168911147554e-09 1 1.5700000469740278
        children [
          DEF WHEEL Shape {
            appearance PBRAppearance {
              metalness 0
            }
            geometry DEF ROBOT_WHEEL_LEFT Cylinder {
              height 0.006
              radius 0.017
            }
          }
        ]
        boundingObject USE WHEEL
        physics DEF WHEEL_PHYS Physics {
        }
      }
    }
    DEF BODY Shape {
      appearance PBRAppearance {
        baseColor 1 0 0
        metalness 0
      }
      geometry DEF ROBOT_BASE Cylinder {
        height 0.035
        radius 0.03
      }
    }
  ]
  boundingObject USE BODY
  physics Physics {
  }
  controller "first_controller"
  supervisor TRUE
}
